<?xml version="1.0" ?>
<robot name="omni" xmlns:xacro="http://www.ros.org/wiki/xacro">

<xacro:include filename="$(find omni_description)/urdf/materials.xacro" />
<xacro:include filename="$(find omni_description)/urdf/omni.trans" />
<xacro:include filename="$(find omni_description)/urdf/omni.gazebo" />

<link name="base_link">
  <inertial>
    <origin xyz="-0.09773323828228454 0.0007226627833107346 0.022411911514028184" rpy="0 0 0"/>
    <mass value="4.252201155500529"/>
    <inertia ixx="0.008087" iyy="0.02462" izz="0.024706" ixy="0.000186" iyz="-0.000351" ixz="0.003179"/>
  </inertial>
  <visual>
    <origin xyz="0 0 0" rpy="0 0 0"/>
    <geometry>
      <mesh filename="package://omni_description/meshes/base_link.stl"/>
    </geometry>
    <material name="silver"/>
  </visual>
  <collision>
    <origin xyz="0 0 0" rpy="0 0 0"/>
    <geometry>
      <mesh filename="package://omni_description/meshes/base_link.stl"/>
    </geometry>
  </collision>
</link>

<link name="hokuyo_1">
  <inertial>
    <origin xyz="2.336606508279715e-08 3.8184287998466193e-07 0.020883564035625468" rpy="0 0 0"/>
    <mass value="0.3480480361849981"/>
    <inertia ixx="8.4e-05" iyy="8.4e-05" izz="5.4e-05" ixy="0.0" iyz="0.0" ixz="-0.0"/>
  </inertial>
  <visual>
    <origin xyz="0.093332 7.5e-05 -0.119283" rpy="0 0 0"/>
    <geometry>
      <mesh filename="package://omni_description/meshes/hokuyo_1.stl"/>
    </geometry>
    <material name="silver"/>
  </visual>
  <collision>
    <origin xyz="0.093332 7.5e-05 -0.119283" rpy="0 0 0"/>
    <geometry>
      <mesh filename="package://omni_description/meshes/hokuyo_1.stl"/>
    </geometry>
  </collision>
</link>

<link name="camera_1">
  <inertial>
    <origin xyz="0.0447948568203564 3.841191200996773e-07 0.030958820986335858" rpy="0 0 0"/>
    <mass value="0.5924464749290492"/>
    <inertia ixx="0.000234" iyy="0.000644" izz="0.000711" ixy="-0.0" iyz="-0.0" ixz="-0.000116"/>
  </inertial>
  <visual>
    <origin xyz="0.120832 7.5e-05 -0.075283" rpy="0 0 0"/>
    <geometry>
      <mesh filename="package://omni_description/meshes/camera_1.stl"/>
    </geometry>
    <material name="silver"/>
  </visual>
  <collision>
    <origin xyz="0.120832 7.5e-05 -0.075283" rpy="0 0 0"/>
    <geometry>
      <mesh filename="package://omni_description/meshes/camera_1.stl"/>
    </geometry>
  </collision>
</link>

<link name="base_footprint_1">
  <inertial>
    <origin xyz="0.011015526351477817 -1.2132936514437287e-05 -0.02025971413965761" rpy="0 0 0"/>
    <mass value="2.8579441590973205"/>
    <inertia ixx="0.007001" iyy="0.015233" izz="0.021212" ixy="-6e-06" iyz="5e-06" ixz="0.00016"/>
  </inertial>
  <visual>
    <origin xyz="0.120832 7.5e-05 0.012717" rpy="0 0 0"/>
    <geometry>
      <mesh filename="package://omni_description/meshes/base_footprint_1.stl"/>
    </geometry>
    <material name="silver"/>
  </visual>
  <collision>
    <origin xyz="0.120832 7.5e-05 0.012717" rpy="0 0 0"/>
    <geometry>
      <mesh filename="package://omni_description/meshes/base_footprint_1.stl"/>
    </geometry>
  </collision>
</link>

<link name="front_r_wheel_1">
  <inertial>
    <origin xyz="-0.0002458235682244632 -0.01366320983047506 0.0007562614815726718" rpy="0 0 0"/>
    <mass value="0.35644460676611167"/>
    <inertia ixx="8.9e-05" iyy="0.000135" izz="8.3e-05" ixy="-0.0" iyz="-0.0" ixz="2e-06"/>
  </inertial>
  <visual>
    <origin xyz="0.019989 0.084575 0.037717" rpy="0 0 0"/>
    <geometry>
      <mesh filename="package://omni_description/meshes/front_r_wheel_1.stl"/>
    </geometry>
    <material name="silver"/>
  </visual>
  <collision>
    <origin xyz="0.019989 0.084575 0.037717" rpy="0 0 0"/>
    <geometry>
      <mesh filename="package://omni_description/meshes/front_r_wheel_1.stl"/>
    </geometry>
  </collision>
</link>

<link name="front_l_wheel_1">
  <inertial>
    <origin xyz="-0.00024582318146064083 0.013663923828028529 0.0007562586384524256" rpy="0 0 0"/>
    <mass value="0.35644606430630343"/>
    <inertia ixx="8.9e-05" iyy="0.000135" izz="8.3e-05" ixy="0.0" iyz="0.0" ixz="2e-06"/>
  </inertial>
  <visual>
    <origin xyz="0.019989 -0.084425 0.037717" rpy="0 0 0"/>
    <geometry>
      <mesh filename="package://omni_description/meshes/front_l_wheel_1.stl"/>
    </geometry>
    <material name="silver"/>
  </visual>
  <collision>
    <origin xyz="0.019989 -0.084425 0.037717" rpy="0 0 0"/>
    <geometry>
      <mesh filename="package://omni_description/meshes/front_l_wheel_1.stl"/>
    </geometry>
  </collision>
</link>

<link name="back_l_wheel_1">
  <inertial>
    <origin xyz="0.0007562654193716267 0.017563160142214207 0.000245765096680943" rpy="0 0 0"/>
    <mass value="0.3564460643063053"/>
    <inertia ixx="8.3e-05" iyy="0.000135" izz="8.9e-05" ixy="0.0" iyz="-0.0" ixz="-2e-06"/>
  </inertial>
  <visual>
    <origin xyz="0.193332 -0.076975 0.037717" rpy="0 0 0"/>
    <geometry>
      <mesh filename="package://omni_description/meshes/back_l_wheel_1.stl"/>
    </geometry>
    <material name="silver"/>
  </visual>
  <collision>
    <origin xyz="0.193332 -0.076975 0.037717" rpy="0 0 0"/>
    <geometry>
      <mesh filename="package://omni_description/meshes/back_l_wheel_1.stl"/>
    </geometry>
  </collision>
</link>

<link name="back_r_wheel_1">
  <inertial>
    <origin xyz="0.0007562682625465444 -0.0175632098305587 0.0002457654835497994" rpy="0 0 0"/>
    <mass value="0.35644460676611395"/>
    <inertia ixx="8.3e-05" iyy="0.000135" izz="8.9e-05" ixy="-0.0" iyz="0.0" ixz="-2e-06"/>
  </inertial>
  <visual>
    <origin xyz="0.193332 0.077575 0.037717" rpy="0 0 0"/>
    <geometry>
      <mesh filename="package://omni_description/meshes/back_r_wheel_1.stl"/>
    </geometry>
    <material name="silver"/>
  </visual>
  <collision>
    <origin xyz="0.193332 0.077575 0.037717" rpy="0 0 0"/>
    <geometry>
      <mesh filename="package://omni_description/meshes/back_r_wheel_1.stl"/>
    </geometry>
  </collision>
</link>

<joint name="hokuyo_j" type="fixed">
  <origin xyz="0.0275 0.0 0.044" rpy="0 0 0"/>
  <parent link="camera_1"/>
  <child link="hokuyo_1"/>
</joint>

<joint name="camera_j" type="fixed">
  <origin xyz="-0.120832 -7.5e-05 0.075283" rpy="0 0 0"/>
  <parent link="base_link"/>
  <child link="camera_1"/>
</joint>

<joint name="Rigid 17" type="fixed">
  <origin xyz="-0.120832 -7.5e-05 -0.012717" rpy="0 0 0"/>
  <parent link="base_link"/>
  <child link="base_footprint_1"/>
</joint>

<joint name="front_r_wheel_j" type="continuous">
  <origin xyz="0.100843 -0.0845 -0.025" rpy="0 0 0"/>
  <parent link="base_footprint_1"/>
  <child link="front_r_wheel_1"/>
  <axis xyz="-0.0 1.0 0.0"/>
</joint>

<joint name="front_l_wheel_j" type="continuous">
  <origin xyz="0.100843 0.0845 -0.025" rpy="0 0 0"/>
  <parent link="base_footprint_1"/>
  <child link="front_l_wheel_1"/>
  <axis xyz="-0.0 1.0 0.0"/>
</joint>

<joint name="back_l_wheel_j" type="continuous">
  <origin xyz="-0.0725 0.07705 -0.025" rpy="0 0 0"/>
  <parent link="base_footprint_1"/>
  <child link="back_l_wheel_1"/>
  <axis xyz="0.0 1.0 -0.0"/>
</joint>

<joint name="back_r_wheel_j" type="continuous">
  <origin xyz="-0.0725 -0.0775 -0.025" rpy="0 0 0"/>
  <parent link="base_footprint_1"/>
  <child link="back_r_wheel_1"/>
  <axis xyz="-0.0 1.0 0.0"/>
</joint>

<!-- hokuyo -->
<gazebo reference="hokuyo_1">
  <sensor type="gpu_ray" name="head_hokuyo_sensor">
    <pose>0 0 0 0 0 0</pose>
    <visualize>false</visualize>
    <update_rate>40</update_rate>
    <ray>
      <scan>
        <horizontal>
          <samples>720</samples>
          <resolution>1</resolution>
          <min_angle>-1.570796</min_angle>
          <max_angle>1.570796</max_angle>
        </horizontal>
      </scan>
      <range>
        <min>0.10</min>
        <max>30.0</max>
        <resolution>0.01</resolution>
      </range>
      <noise>
        <type>gaussian</type>
        <!-- Noise parameters based on published spec for Hokuyo laser
              achieving "+-30mm" accuracy at range < 10m.  A mean of 0.0m and
              stddev of 0.01m will put 99.7% of samples within 0.03m of the true
              reading. -->
        <mean>0.0</mean>
        <stddev>0.01</stddev>
      </noise>
    </ray>
    <plugin name="gazebo_ros_head_hokuyo_controller" filename="libgazebo_ros_gpu_laser.so">
      <topicName>/laser/scan</topicName>
      <frameName>hokuyo_link</frameName>
    </plugin>
  </sensor>
</gazebo>

<gazebo>
  <plugin name="object_controller" filename="libgazebo_ros_planar_move.so">
    <commandTopic>cmd_vel</commandTopic>
    <odometryTopic>odom</odometryTopic>
    <odometryFrame>odom</odometryFrame>
    <odometryRate>20.0</odometryRate>
    <robotBaseFrame>base_footprint</robotBaseFrame>
  </plugin>
</gazebo>

</robot>
